<robot name="handright01091">

  <link name="world" />
  <joint name="fixed" type="fixed">
    <origin xyz="0 0 0" rpy="-1.5707963 0 0" />
    <parent link="world" />
    <child link="link_RArm7" />
  </joint>

  <link name="link_RArm7">
    <inertial>
      <origin xyz="-0.0014001 -0.052388 0.00224" rpy="0 0 0" />
      <mass value="0.10331" />
      <inertia ixx="9.8144E-05" ixy="3.186E-06" ixz="1.4747E-06" iyy="6.4614E-05" iyz="-2.412E-06" izz="5.5134E-05" />
    </inertial>
    <visual>
      <origin xyz="0 0 0" rpy="0 0 0" />
      <geometry>
        <mesh filename="package://handright01091/meshes/base_link.STL" />
      </geometry>
      <material name="">
        <color rgba="1 1 1 1" />
      </material>
    </visual>
    <collision>
      <origin xyz="0 0 0" rpy="0 0 0" />
      <geometry>
        <mesh filename="package://handright01091/meshes/base_link.STL" />
      </geometry>
    </collision>
  </link>
  <link name="link_RArm8">
    <inertial>
      <origin xyz="-0.0048064 0.0009382 -0.00757" rpy="0 0 0" />
      <mass value="0.0018869" />
      <inertia ixx="5.816E-08" ixy="1.4539E-08" ixz="4.491E-09" iyy="7.9161E-08" iyz="-1.8727E-09" izz="6.7433E-08" />
    </inertial>
    <visual>
      <origin xyz="0 0 0" rpy="0 0 0" />
      <geometry>
        <mesh filename="package://handright01091/meshes/Link11.STL" />
      </geometry>
      <material name="">
        <color rgba="1 1 1 1" />
      </material>
    </visual>
    <collision>
      <origin xyz="0 0 0" rpy="0 0 0" />
      <geometry>
        <mesh filename="package://handright01091/meshes/Link11.STL" />
      </geometry>
    </collision>
  </link>
  <joint name="joint_RFinger0" type="revolute">
    <origin xyz="-0.01496 -0.0375 -0.02045" rpy="1.5708 -1.5708 0" />
    <parent link="link_RArm7" />
    <child link="link_RArm8" />
    <axis xyz="0 0 -1" />
    <limit lower="0" upper="1.30" effort="50" velocity="0.1" />
  </joint>
  <link name="link_RArm9">
    <inertial>
      <origin xyz="0.021932 0.012785 -0.0080386" rpy="0 0 0" />
      <mass value="0.0066075" />
      <inertia ixx="1.5686E-06" ixy="-7.8296E-07" ixz="8.9143E-10" iyy="1.7353E-06" iyz="-1.0191E-09" izz="2.786E-06" />
    </inertial>
    <visual>
      <origin xyz="0 0 0" rpy="0 0 0" />
      <geometry>
        <mesh filename="package://handright01091/meshes/Link12.STL" />
      </geometry>
      <material name="">
        <color rgba="1 1 1 1" />
      </material>
    </visual>
    <collision>
      <origin xyz="0 0 0" rpy="0 0 0" />
      <geometry>
        <mesh filename="package://handright01091/meshes/Link12.STL" />
      </geometry>
    </collision>
  </link>
  <joint name="joint_RFinger1" type="revolute">
    <origin xyz="-0.0088099 0.010892 -0.00925" rpy="1.5708 0 2.8587" />
    <parent link="link_RArm8" />
    <child link="link_RArm9" />
    <axis xyz="0 0 1" />
    <limit lower="0" upper="0.68" effort="50" velocity="0.1" />
  </joint>
  <link name="link_RArm10">
    <inertial>
      <origin xyz="0.0095544 -0.0016282 -0.0071997" rpy="0 0 0" />
      <mass value="0.0037847" />
      <inertia ixx="3.6981E-07" ixy="-9.8581E-08" ixz="-4.7468E-12" iyy="3.2394E-07" iyz="1.094E-12" izz="4.6531E-07" />
    </inertial>
    <visual>
      <origin xyz="0 0 0" rpy="0 0 0" />
      <geometry>
        <mesh filename="package://handright01091/meshes/Link13.STL" />
      </geometry>
      <material name="">
        <color rgba="1 1 1 1" />
      </material>
    </visual>
    <collision>
      <origin xyz="0 0 0" rpy="0 0 0" />
      <geometry>
        <mesh filename="package://handright01091/meshes/Link13.STL" />
      </geometry>
    </collision>
  </link>
  <joint name="joint_RFinger2" type="revolute">
    <origin xyz="0.04407 0.034553 -0.0008" rpy="0 0 0" />
    <parent link="link_RArm9" />
    <child link="link_RArm10" />
    <axis xyz="0 0 1" />
    <limit lower="0" upper="0.77" effort="50" velocity="0.1" />
  </joint>
  <link name="link_RArm11">
    <inertial>
      <origin xyz="0.0092888 0.0049529 -0.0060033" rpy="0 0 0" />
      <mass value="0.0033441" />
      <inertia ixx="1.3632E-07" ixy="-5.6788E-08" ixz="-9.2764E-11" iyy="1.4052E-07" iyz="-1.2283E-10" izz="2.0026E-07" />
    </inertial>
    <visual>
      <origin xyz="0 0 0" rpy="0 0 0" />
      <geometry>
        <mesh filename="package://handright01091/meshes/Link14.STL" />
      </geometry>
      <material name="">
        <color rgba="1 1 1 1" />
      </material>
    </visual>
    <collision>
      <origin xyz="0 0 0" rpy="0 0 0" />
      <geometry>
        <mesh filename="package://handright01091/meshes/Link14.STL" />
      </geometry>
    </collision>
  </link>
  <joint name="joint_RFinger3" type="revolute">
    <origin xyz="0.020248 0.010156 -0.0012" rpy="0 0 0" />
    <parent link="link_RArm10" />
    <child link="link_RArm11" />
    <axis xyz="0 0 1" />
    <dynamics damping="0.0001" friction="0.0" />
    <limit lower="0" upper="0.597" effort="50" velocity="0.1" />
  </joint>
  <link name="link_RArm12">
    <visual>
      <origin xyz="0 0 0" rpy="0 0 0" />
      <geometry>
        <sphere radius="0.004" />
      </geometry>
      <material name="">
        <color rgba="1 0 0 1" />
      </material>
    </visual>
  </link>
  <joint name="joint_RFinger4" type="fixed">
    <origin xyz="0.0178 0.011 -0.006" rpy="0 0 0" />
    <parent link="link_RArm11" />
    <child link="link_RArm12" />
  </joint>
  <link name="link_RArm13">
    <inertial>
      <origin xyz="0.0012259 0.011942 -0.0060001" rpy="0 0 0" />
      <mass value="0.0042403" />
      <inertia ixx="6.6232E-07" ixy="-1.5775E-08" ixz="1.8577E-12" iyy="2.1146E-07" iyz="-5.0615E-12" izz="6.9398E-07" />
    </inertial>
    <visual>
      <origin xyz="0 0 0" rpy="0 0 0" />
      <geometry>
        <mesh filename="package://handright01091/meshes/Link15.STL" />
      </geometry>
      <material name="">
        <color rgba="1 1 1 1" />
      </material>
    </visual>
    <collision>
      <origin xyz="0 0 0" rpy="0 0 0" />
      <geometry>
        <mesh filename="package://handright01091/meshes/Link15.STL" />
      </geometry>
    </collision>
  </link>
  <joint name="joint_RFinger5" type="revolute">
    <origin xyz="0.0022853 -0.10493 -0.032268" rpy="-3.1067 0 0" />
    <parent link="link_RArm7" />
    <child link="link_RArm13" />
    <axis xyz="0 0 1" />
    <limit lower="0" upper="1.62" effort="50" velocity="0.1" />
  </joint>
  <link name="link_RArm14">
    <inertial>
      <origin xyz="0.0019697 0.019589 -0.005" rpy="0 0 0" />
      <mass value="0.0045683" />
      <inertia ixx="7.6111E-07" ixy="8.7637E-08" ixz="-3.7738E-13" iyy="9.6076E-08" iyz="9.9488E-13" izz="7.8179E-07" />
    </inertial>
    <visual>
      <origin xyz="0 0 0" rpy="0 0 0" />
      <geometry>
        <mesh filename="package://handright01091/meshes/Link16.STL" />
      </geometry>
      <material name="">
        <color rgba="1 1 1 1" />
      </material>
    </visual>
    <collision>
      <origin xyz="0 0 0" rpy="0 0 0" />
      <geometry>
        <mesh filename="package://handright01091/meshes/Link16.STL" />
      </geometry>
    </collision>
  </link>
  <joint name="joint_RFinger6" type="revolute">
    <origin xyz="-0.0026138 0.032026 -0.001" rpy="0 0 0" />
    <parent link="link_RArm13" />
    <child link="link_RArm14" />
    <axis xyz="0 0 1" />
    <dynamics damping="0.0001" friction="0.0" />
    <limit lower="0" upper="1.82" effort="0" velocity="0.1" />
  </joint>
  <link name="link_RArm15">
    <visual>
      <origin xyz="0 0 0" rpy="0 0 0" />
      <geometry>
        <sphere radius="0.004" />
      </geometry>
      <material name="">
        <color rgba="1 0 0 1" />
      </material>
    </visual>
  </link>
  <joint name="joint_RFinger7" type="fixed">
    <origin xyz="-0.0012 0.041 -0.005" rpy="0 0 0" />
    <parent link="link_RArm14" />
    <child link="link_RArm15" />
  </joint>
  <link name="link_RArm16">
    <inertial>
      <origin xyz="0.001297 0.011934 -0.0060001" rpy="0 0 0" />
      <mass value="0.0042403" />
      <inertia ixx="6.6211E-07" ixy="-1.8461E-08" ixz="1.8067E-12" iyy="2.1167E-07" iyz="-6.6592E-12" izz="6.9397E-07" />
    </inertial>
    <visual>
      <origin xyz="0 0 0" rpy="0 0 0" />
      <geometry>
        <mesh filename="package://handright01091/meshes/Link17.STL" />
      </geometry>
      <material name="">
        <color rgba="1 1 1 1" />
      </material>
    </visual>
    <collision>
      <origin xyz="0 0 0" rpy="0 0 0" />
      <geometry>
        <mesh filename="package://handright01091/meshes/Link17.STL" />
      </geometry>
    </collision>
  </link>
  <joint name="joint_RFinger8" type="revolute">
    <origin xyz="0.0022853 -0.1055 -0.01295" rpy="-3.1416 0 0" />
    <parent link="link_RArm7" />
    <child link="link_RArm16" />
    <axis xyz="0 0 1" />
    <limit lower="0" upper="1.62" effort="50" velocity="0.1" />
  </joint>
  <link name="link_RArm17">
    <inertial>
      <origin xyz="0.001921 0.020796 -0.005" rpy="0 0 0" />
      <mass value="0.0050396" />
      <inertia ixx="9.5822E-07" ixy="1.1425E-07" ixz="-2.4791E-12" iyy="1.0646E-07" iyz="5.9173E-12" izz="9.8384E-07" />
    </inertial>
    <visual>
      <origin xyz="0 0 0" rpy="0 0 0" />
      <geometry>
        <mesh filename="package://handright01091/meshes/Link18.STL" />
      </geometry>
      <material name="">
        <color rgba="1 1 1 1" />
      </material>
    </visual>
    <collision>
      <origin xyz="0 0 0" rpy="0 0 0" />
      <geometry>
        <mesh filename="package://handright01091/meshes/Link18.STL" />
      </geometry>
    </collision>
  </link>
  <joint name="joint_RFinger9" type="revolute">
    <origin xyz="-0.0024229 0.032041 -0.001" rpy="0 0 0" />
    <parent link="link_RArm16" />
    <child link="link_RArm17" />
    <axis xyz="0 0 1" />
    <dynamics damping="0.0001" friction="0.0" />
    <limit lower="0" upper="1.75" effort="50" velocity="0.1" />
  </joint>
  <link name="link_RArm18">
    <visual>
      <origin xyz="0 0 0" rpy="0 0 0" />
      <geometry>
        <sphere radius="0.004" />
      </geometry>
      <material name="">
        <color rgba="1 0 0 1" />
      </material>
    </visual>
  </link>
  <joint name="joint_RFinger10" type="fixed">
    <origin xyz="-0.0015 0.0445 -0.005" rpy="0 0 0" />
    <parent link="link_RArm17" />
    <child link="link_RArm18" />
  </joint>
  <link name="link_RArm19">
    <inertial>
      <origin xyz="0.001297 0.011934 -0.0060002" rpy="0 0 0" />
      <mass value="0.0042403" />
      <inertia ixx="6.6211E-07" ixy="-1.8461E-08" ixz="1.5859E-12" iyy="2.1167E-07" iyz="-6.6649E-12" izz="6.9397E-07" />
    </inertial>
    <visual>
      <origin xyz="0 0 0" rpy="0 0 0" />
      <geometry>
        <mesh filename="package://handright01091/meshes/Link19.STL" />
      </geometry>
      <material name="">
        <color rgba="1 1 1 1" />
      </material>
    </visual>
    <collision>
      <origin xyz="0 0 0" rpy="0 0 0" />
      <geometry>
        <mesh filename="package://handright01091/meshes/Link19.STL" />
      </geometry>
    </collision>
  </link>
  <joint name="joint_RFinger11" type="revolute">
    <origin xyz="0.0022853 -0.10531 0.0062872" rpy="3.0892 0 0" />
    <parent link="link_RArm7" />
    <child link="link_RArm19" />
    <axis xyz="0 0 1" />
    <limit lower="0" upper="1.62" effort="50" velocity="0.1" />
  </joint>
  <link name="link_RArm20">
    <inertial>
      <origin xyz="0.0021753 0.019567 -0.005" rpy="0 0 0" />
      <mass value="0.0045683" />
      <inertia ixx="7.6286E-07" ixy="8.0635E-08" ixz="-6.1562E-13" iyy="9.431E-08" iyz="5.8619E-13" izz="7.8177E-07" />
    </inertial>
    <visual>
      <origin xyz="0 0 0" rpy="0 0 0" />
      <geometry>
        <mesh filename="package://handright01091/meshes/Link20.STL" />
      </geometry>
      <material name="">
        <color rgba="1 1 1 1" />
      </material>
    </visual>
    <collision>
      <origin xyz="0 0 0" rpy="0 0 0" />
      <geometry>
        <mesh filename="package://handright01091/meshes/Link20.STL" />
      </geometry>
    </collision>
  </link>
  <joint name="joint_RFinger12" type="revolute">
    <origin xyz="-0.0024229 0.032041 -0.001" rpy="0 0 0" />
    <parent link="link_RArm19" />
    <child link="link_RArm20" />
    <axis xyz="0 0 1" />
    <dynamics damping="0.0001" friction="0.0" />
    <limit lower="0" upper="1.75" effort="50" velocity="0.1" />
  </joint>
  <link name="link_RArm21">
    <visual>
      <origin xyz="0 0 0" rpy="0 0 0" />
      <geometry>
        <sphere radius="0.004" />
      </geometry>
      <material name="">
        <color rgba="1 0 0 1" />
      </material>
    </visual>
  </link>
  <joint name="joint_RFinger13" type="fixed">
    <origin xyz="-0.0008 0.041 -0.005" rpy="0 0 0" />
    <parent link="link_RArm20" />
    <child link="link_RArm21" />
  </joint>
  <link name="link_RArm22">
    <inertial>
      <origin xyz="0.001297 0.011934 -0.0060001" rpy="0 0 0" />
      <mass value="0.0042403" />
      <inertia ixx="6.6211E-07" ixy="-1.8461E-08" ixz="1.6972E-12" iyy="2.1167E-07" iyz="-6.9116E-12" izz="6.9397E-07" />
    </inertial>
    <visual>
      <origin xyz="0 0 0" rpy="0 0 0" />
      <geometry>
        <mesh filename="package://handright01091/meshes/Link21.STL" />
      </geometry>
      <material name="">
        <color rgba="1 1 1 1" />
      </material>
    </visual>
    <collision>
      <origin xyz="0 0 0" rpy="0 0 0" />
      <geometry>
        <mesh filename="package://handright01091/meshes/Link21.STL" />
      </geometry>
    </collision>
  </link>
  <joint name="joint_RFinger14" type="revolute">
    <origin xyz="0.0022853 -0.10411 0.025488" rpy="3.0369 0 0" />
    <parent link="link_RArm7" />
    <child link="link_RArm22" />
    <axis xyz="0 0 1" />
    <limit lower="0" upper="1.62" effort="50" velocity="0.1" />
  </joint>
  <link name="link_RArm23">
    <inertial>
      <origin xyz="0.0024748 0.016203 -0.0050031" rpy="0 0 0" />
      <mass value="0.0035996" />
      <inertia ixx="4.3913E-07" ixy="4.1418E-08" ixz="3.7168E-11" iyy="7.0247E-08" iyz="5.8613E-11" izz="4.4867E-07" />
    </inertial>
    <visual>
      <origin xyz="0 0 0" rpy="0 0 0" />
      <geometry>
        <mesh filename="package://handright01091/meshes/Link22.STL" />
      </geometry>
      <material name="">
        <color rgba="1 1 1 1" />
      </material>
    </visual>
    <collision>
      <origin xyz="0 0 0" rpy="0 0 0" />
      <geometry>
        <mesh filename="package://handright01091/meshes/Link22.STL" />
      </geometry>
    </collision>
  </link>
  <joint name="joint_RFinger15" type="revolute">
    <origin xyz="-0.0024229 0.032041 -0.001" rpy="0 0 0" />
    <parent link="link_RArm22" />
    <child link="link_RArm23" />
    <axis xyz="0 0 1" />
    <dynamics damping="0.0001" friction="0.0" />
    <limit lower="0" upper="1.87" effort="50" velocity="0.1" />
  </joint>
  <link name="link_RArm24">
    <visual>
      <origin xyz="0 0 0" rpy="0 0 0" />
      <geometry>
        <sphere radius="0.004" />
      </geometry>
      <material name="">
        <color rgba="1 0 0 1" />
      </material>
    </visual>
  </link>
  <joint name="joint_RFinger16" type="fixed">
    <origin xyz="-0.0002 0.0333 -0.005" rpy="0 0 0" />
    <parent link="link_RArm23" />
    <child link="link_RArm24" />
  </joint>


  <gazebo>
   <plugin name="gazebo_ros_control" filename="libgazebo_ros_control.so">
    <robotNamespace>/swivel</robotNamespace>
    <controlPeriod>0.001</controlPeriod>
    <robotSimType>gazebo_ros_control/DefaultRobotHWSim</robotSimType>
   </plugin>
  </gazebo>

  <transmission name="tran1">
   <type>transmission_interface/SimpleTransmission</type>
   <joint name="joint011">
    <hardwareInterface>hardware_interface/EffortJointInterface</hardwareInterface>
   </joint>
   <actuator name="motor1">
    <hardwareInterface>hardware_interface/EffortJointInterface</hardwareInterface>
    <mechanicalReduction>1</mechanicalReduction>
   </actuator>
  </transmission>

  <transmission name="tran2">
   <type>transmission_interface/SimpleTransmission</type>
   <joint name="joint1112">
    <hardwareInterface>hardware_interface/EffortJointInterface</hardwareInterface>
   </joint>
   <actuator name="motor2">
    <hardwareInterface>hardware_interface/EffortJointInterface</hardwareInterface>
    <mechanicalReduction>1</mechanicalReduction>
   </actuator>
  </transmission>

  <transmission name="tran3">
   <type>transmission_interface/SimpleTransmission</type>
   <joint name="joint015">
    <hardwareInterface>hardware_interface/EffortJointInterface</hardwareInterface>
   </joint>
   <actuator name="motor3">
    <hardwareInterface>hardware_interface/EffortJointInterface</hardwareInterface>
    <mechanicalReduction>1</mechanicalReduction>
   </actuator>
  </transmission>

  <transmission name="tran4">
   <type>transmission_interface/SimpleTransmission</type>
   <joint name="joint017">
    <hardwareInterface>hardware_interface/EffortJointInterface</hardwareInterface>
   </joint>
   <actuator name="motor4">
    <hardwareInterface>hardware_interface/EffortJointInterface</hardwareInterface>
    <mechanicalReduction>1</mechanicalReduction>
   </actuator>
  </transmission>

  <transmission name="tran5">
   <type>transmission_interface/SimpleTransmission</type>
   <joint name="joint019">
    <hardwareInterface>hardware_interface/EffortJointInterface</hardwareInterface>
   </joint>
   <actuator name="motor5">
    <hardwareInterface>hardware_interface/EffortJointInterface</hardwareInterface>
    <mechanicalReduction>1</mechanicalReduction>
   </actuator>
  </transmission>

  <transmission name="tran6">
   <type>transmission_interface/SimpleTransmission</type>
   <joint name="joint021">
    <hardwareInterface>hardware_interface/EffortJointInterface</hardwareInterface>
   </joint>
   <actuator name="motor6">
    <hardwareInterface>hardware_interface/EffortJointInterface</hardwareInterface>
    <mechanicalReduction>1</mechanicalReduction>
   </actuator>
  </transmission>


</robot>
